2016-10-14 22:33:37,011 12s ERROR    Internal Server Error: /get_evnt_by_name
Traceback (most recent call last):
  File "/usr/local/lib/python2.7/dist-packages/django/core/handlers/exception.py", line 39, in inner
    response = get_response(request)
  File "/usr/local/lib/python2.7/dist-packages/django/core/handlers/base.py", line 187, in _get_response
    response = self.process_exception_by_middleware(e, request)
  File "/usr/local/lib/python2.7/dist-packages/django/core/handlers/base.py", line 185, in _get_response
    response = wrapped_callback(request, *callback_args, **callback_kwargs)
  File "/usr/local/lib/python2.7/dist-packages/django/views/decorators/csrf.py", line 58, in wrapped_view
    return view_func(*args, **kwargs)
  File "/home/glopez/Apps/fluid-integrates/app/views.py", line 71, in get_evnt_by_name
    result = models.get_evnt_by_name(project)
  File "/home/glopez/Apps/fluid-integrates/app/models.py", line 206, in get_evnt_by_name
    result = requests.get(url, data=data, verify=False, headers=CONFIG['headers'])
  File "/usr/lib/python2.7/dist-packages/requests/api.py", line 67, in get
    return request('get', url, params=params, **kwargs)
  File "/usr/lib/python2.7/dist-packages/requests/api.py", line 53, in request
    return session.request(method=method, url=url, **kwargs)
  File "/usr/lib/python2.7/dist-packages/requests/sessions.py", line 468, in request
    resp = self.send(prep, **send_kwargs)
  File "/usr/lib/python2.7/dist-packages/requests/sessions.py", line 576, in send
    r = adapter.send(request, **kwargs)
  File "/usr/lib/python2.7/dist-packages/requests/adapters.py", line 437, in send
    raise ConnectionError(e, request=request)
ConnectionError: HTTPSConnectionPool(host='www.formstack.com', port=443): Max retries exceeded with url: /api/v2/form/1886931/submission.json (Caused by NewConnectionError('<requests.packages.urllib3.connection.VerifiedHTTPSConnection object at 0x7f24dd397a50>: Failed to establish a new connection: [Errno -2] Name or service not known',))
2016-10-14 22:47:35,675 12s ERROR    Internal Server Error: /get_evnt_by_name
Traceback (most recent call last):
  File "/usr/local/lib/python2.7/dist-packages/django/core/handlers/exception.py", line 39, in inner
    response = get_response(request)
  File "/usr/local/lib/python2.7/dist-packages/django/core/handlers/base.py", line 187, in _get_response
    response = self.process_exception_by_middleware(e, request)
  File "/usr/local/lib/python2.7/dist-packages/django/core/handlers/base.py", line 185, in _get_response
    response = wrapped_callback(request, *callback_args, **callback_kwargs)
  File "/usr/local/lib/python2.7/dist-packages/django/views/decorators/csrf.py", line 58, in wrapped_view
    return view_func(*args, **kwargs)
  File "/home/glopez/Apps/fluid-integrates/app/views.py", line 71, in get_evnt_by_name
    result = models.get_evnt_by_name(project)
  File "/home/glopez/Apps/fluid-integrates/app/models.py", line 206, in get_evnt_by_name
    result = requests.get(url, data=data, verify=False, headers=CONFIG['headers'])
  File "/usr/lib/python2.7/dist-packages/requests/api.py", line 67, in get
    return request('get', url, params=params, **kwargs)
  File "/usr/lib/python2.7/dist-packages/requests/api.py", line 53, in request
    return session.request(method=method, url=url, **kwargs)
  File "/usr/lib/python2.7/dist-packages/requests/sessions.py", line 468, in request
    resp = self.send(prep, **send_kwargs)
  File "/usr/lib/python2.7/dist-packages/requests/sessions.py", line 576, in send
    r = adapter.send(request, **kwargs)
  File "/usr/lib/python2.7/dist-packages/requests/adapters.py", line 437, in send
    raise ConnectionError(e, request=request)
ConnectionError: HTTPSConnectionPool(host='www.formstack.com', port=443): Max retries exceeded with url: /api/v2/form/1886931/submission.json (Caused by NewConnectionError('<requests.packages.urllib3.connection.VerifiedHTTPSConnection object at 0x7f24dc30d350>: Failed to establish a new connection: [Errno -2] Name or service not known',))
2016-10-14 23:35:00,167 12s ERROR    Internal Server Error: /get_evnt_by_name
Traceback (most recent call last):
  File "/usr/local/lib/python2.7/dist-packages/django/core/handlers/exception.py", line 39, in inner
    response = get_response(request)
  File "/usr/local/lib/python2.7/dist-packages/django/core/handlers/base.py", line 187, in _get_response
    response = self.process_exception_by_middleware(e, request)
  File "/usr/local/lib/python2.7/dist-packages/django/core/handlers/base.py", line 185, in _get_response
    response = wrapped_callback(request, *callback_args, **callback_kwargs)
  File "/usr/local/lib/python2.7/dist-packages/django/views/decorators/csrf.py", line 58, in wrapped_view
    return view_func(*args, **kwargs)
  File "/home/glopez/Apps/fluid-integrates/app/views.py", line 71, in get_evnt_by_name
    result = models.get_evnt_by_name(project)
  File "/home/glopez/Apps/fluid-integrates/app/models.py", line 206, in get_evnt_by_name
    result = requests.get(url, data=data, verify=False, headers=CONFIG['headers'])
  File "/usr/lib/python2.7/dist-packages/requests/api.py", line 67, in get
    return request('get', url, params=params, **kwargs)
  File "/usr/lib/python2.7/dist-packages/requests/api.py", line 53, in request
    return session.request(method=method, url=url, **kwargs)
  File "/usr/lib/python2.7/dist-packages/requests/sessions.py", line 468, in request
    resp = self.send(prep, **send_kwargs)
  File "/usr/lib/python2.7/dist-packages/requests/sessions.py", line 576, in send
    r = adapter.send(request, **kwargs)
  File "/usr/lib/python2.7/dist-packages/requests/adapters.py", line 437, in send
    raise ConnectionError(e, request=request)
ConnectionError: HTTPSConnectionPool(host='www.formstack.com', port=443): Max retries exceeded with url: /api/v2/form/1886931/submission.json (Caused by NewConnectionError('<requests.packages.urllib3.connection.VerifiedHTTPSConnection object at 0x7f24dd38f210>: Failed to establish a new connection: [Errno -2] Name or service not known',))
2016-10-14 23:36:37,493 12s ERROR    Internal Server Error: /get_evnt_by_name
Traceback (most recent call last):
  File "/usr/local/lib/python2.7/dist-packages/django/core/handlers/exception.py", line 39, in inner
    response = get_response(request)
  File "/usr/local/lib/python2.7/dist-packages/django/core/handlers/base.py", line 187, in _get_response
    response = self.process_exception_by_middleware(e, request)
  File "/usr/local/lib/python2.7/dist-packages/django/core/handlers/base.py", line 185, in _get_response
    response = wrapped_callback(request, *callback_args, **callback_kwargs)
  File "/usr/local/lib/python2.7/dist-packages/django/views/decorators/csrf.py", line 58, in wrapped_view
    return view_func(*args, **kwargs)
  File "/home/glopez/Apps/fluid-integrates/app/views.py", line 71, in get_evnt_by_name
    result = models.get_evnt_by_name(project)
  File "/home/glopez/Apps/fluid-integrates/app/models.py", line 206, in get_evnt_by_name
    result = requests.get(url, data=data, verify=False, headers=CONFIG['headers'])
  File "/usr/lib/python2.7/dist-packages/requests/api.py", line 67, in get
    return request('get', url, params=params, **kwargs)
  File "/usr/lib/python2.7/dist-packages/requests/api.py", line 53, in request
    return session.request(method=method, url=url, **kwargs)
  File "/usr/lib/python2.7/dist-packages/requests/sessions.py", line 468, in request
    resp = self.send(prep, **send_kwargs)
  File "/usr/lib/python2.7/dist-packages/requests/sessions.py", line 576, in send
    r = adapter.send(request, **kwargs)
  File "/usr/lib/python2.7/dist-packages/requests/adapters.py", line 437, in send
    raise ConnectionError(e, request=request)
ConnectionError: HTTPSConnectionPool(host='www.formstack.com', port=443): Max retries exceeded with url: /api/v2/form/1886931/submission.json (Caused by NewConnectionError('<requests.packages.urllib3.connection.VerifiedHTTPSConnection object at 0x7f24dc3004d0>: Failed to establish a new connection: [Errno -2] Name or service not known',))
